Workbook

Sheet 04_AnalyticsReady
A1: Transaction ID | B1: Item | C1: Quantity | D1: Price Per Unit | E1: Total Spent | F1: Payment Method | G1: Location | H1: Transaction Date
A2: TXN_1961373 | B2: Coffee | C2: 2 | D2: 2 | E2: 4 | F2: Credit Card | G2: Takeaway | H2: 45177
A3: TXN_4977031 | B3: Cake | C3: 4 | D3: 3 | E3: 12 | F3: Cash | G3: In-store | H3: 45062
A4: TXN_4271903 | B4: Cookie | C4: 4 | D4: 1 | E4: 4 | F4: Credit Card | G4: In-store | H4: 45126
A5: TXN_7034554 | B5: Salad | C5: 2 | D5: 5 | E5: 10 | F5: N/A | G5: N/A | H5: 45043
A6: TXN_3160411 | B6: Coffee | C6: 2 | D6: 2 | E6: 4 | F6: Digital Wallet | G6: In-store | H6: 45088
A7: TXN_2602893 | B7: Smoothie | C7: 5 | D7: 4 | E7: 20 | F7: Credit Card | G7: N/A | H7: 45016
A8: TXN_4433211 | B8: Cake | C8: 3 | D8: 3 | E8: 9 | F8: N/A | G8: Takeaway | H8: 45205
A9: TXN_6699534 | B9: Sandwich | C9: 4 | D9: 4 | E9: 16 | F9: Cash | G9: N/A | H9: 45227
A10: TXN_4717867 | B10: Cake | C10: 5 | D10: 3 | E10: 15 | F10: N/A | G10: Takeaway | H10: 45135
A11: TXN_2064365 | B11: Sandwich | C11: 5 | D11: 4 | E11: 20 | F11: N/A | G11: In-store | H11: 45291
A12: TXN_2548360 | B12: Salad | C12: 5 | D12: 5 | E12: 25 | F12: Cash | G12: Takeaway | H12: 45237
A13: TXN_3051279 | B13: Sandwich | C13: 2 | D13: 4 | E13: 8 | F13: Credit Card | G13: Takeaway | H13: 2
... A10001: TXN_6170729 | B10001: Sandwich | C10001: 3 | D10001: 4 | E10001: 12 | F10001: Cash | G10001: In-store | H10001: 45237

Sheet 03_CleaningFlow
A1: Transaction ID | B1: Item | C1: Cleaned_Item | D1: Quantity | E1: Cleaned_Quantity | F1: Price Per Unit | G1: Cleaned_PPU | H1: Total Spent | I1: Cleaned_Total Spent | J1: Cleaned_Payment Method | K1: Cleaned_Location | L1: Transaction Date | M1: Cleaned_Transaction Date
A2: TXN_1961373 | B2: Coffee | C2: =IF(OR($B2="Unknown",$B2="Error",$B2=""),IFERROR(VLOOKUP($F2, '02_UnitPriceRef'!$F$3:$G$10,2,FALSE),"N/A"),$B2) -> Coffee | D2: 2 | E2: =IF(OR($D2="ERROR",$D2="UNKNOWN",$D2=""),IFERROR(H2/G2,0),D2) -> 2 | F2: 2 | G2: =IF(OR($F2="ERROR",$F2="UNKNOWN",$F2=""),IFERROR(VLOOKUP($C2,'02_UnitPriceRef'!$E$3:$F$10,2,0),IF(OR($D2="Error",$D2="UNKNOWN",$D2=""),0,H2/D2)),$F2) -> 2 | H2: 4 | I2: =E2*G2 -> 4 | J2: Credit Card | K2: Takeaway | L2: 45177 | M2: =IF(OR(L2="UNKNOWN",L2="ERROR",L2=""),DATE(1900,1,1),L2) -> 45177
A3: TXN_4977031 | B3: Cake | C3: =IF(OR($B3="Unknown",$B3="Error",$B3=""),IFERROR(VLOOKUP($F3, '02_UnitPriceRef'!$F$3:$G$10,2,FALSE),"N/A"),$B3) -> Cake | D3: 4 | E3: =IF(OR($D3="ERROR",$D3="UNKNOWN",$D3=""),IFERROR(H3/G3,0),D3) -> 4 | F3: 3 | G3: =IF(OR($F3="ERROR",$F3="UNKNOWN",$F3=""),IFERROR(VLOOKUP($C3,'02_UnitPriceRef'!$E$3:$F$10,2,0),IF(OR($D3="Error",$D3="UNKNOWN",$D3=""),0,H3/D3)),$F3) -> 3 | H3: 12 | I3: =E3*G3 -> 12 | J3: Cash | K3: In-store | L3: 45062 | M3: =IF(OR(L3="UNKNOWN",L3="ERROR",L3=""),DATE(1900,1,1),L3) -> 45062
A4: TXN_4271903 | B4: Cookie | C4: =IF(OR($B4="Unknown",$B4="Error",$B4=""),IFERROR(VLOOKUP($F4, '02_UnitPriceRef'!$F$3:$G$10,2,FALSE),"N/A"),$B4) -> Cookie | D4: 4 | E4: =IF(OR($D4="ERROR",$D4="UNKNOWN",$D4=""),IFERROR(H4/G4,0),D4) -> 4 | F4: 1 | G4: =IF(OR($F4="ERROR",$F4="UNKNOWN",$F4=""),IFERROR(VLOOKUP($C4,'02_UnitPriceRef'!$E$3:$F$10,2,0),IF(OR($D4="Error",$D4="UNKNOWN",$D4=""),0,H4/D4)),$F4) -> 1 | H4: ERROR | I4: =E4*G4 -> 4 | J4: Credit Card | K4: In-store | L4: 45126 | M4: =IF(OR(L4="UNKNOWN",L4="ERROR",L4=""),DATE(1900,1,1),L4) -> 45126
A5: TXN_7034554 | B5: Salad | C5: =IF(OR($B5="Unknown",$B5="Error",$B5=""),IFERROR(VLOOKUP($F5, '02_UnitPriceRef'!$F$3:$G$10,2,FALSE),"N/A"),$B5) -> Salad | D5: 2 | E5: =IF(OR($D5="ERROR",$D5="UNKNOWN",$D5=""),IFERROR(H5/G5,0),D5) -> 2 | F5: 5 | G5: =IF(OR($F5="ERROR",$F5="UNKNOWN",$F5=""),IFERROR(VLOOKUP($C5,'02_UnitPriceRef'!$E$3:$F$10,2,0),IF(OR($D5="Error",$D5="UNKNOWN",$D5=""),0,H5/D5)),$F5) -> 5 | H5: 10 | I5: =E5*G5 -> 10 | J5: N/A | K5: N/A | L5: 45043 | M5: =IF(OR(L5="UNKNOWN",L5="ERROR",L5=""),DATE(1900,1,1),L5) -> 45043
A6: TXN_3160411 | B6: Coffee | C6: =IF(OR($B6="Unknown",$B6="Error",$B6=""),IFERROR(VLOOKUP($F6, '02_UnitPriceRef'!$F$3:$G$10,2,FALSE),"N/A"),$B6) -> Coffee | D6: 2 | E6: =IF(OR($D6="ERROR",$D6="UNKNOWN",$D6=""),IFERROR(H6/G6,0),D6) -> 2 | F6: 2 | G6: =IF(OR($F6="ERROR",$F6="UNKNOWN",$F6=""),IFERROR(VLOOKUP($C6,'02_UnitPriceRef'!$E$3:$F$10,2,0),IF(OR($D6="Error",$D6="UNKNOWN",$D6=""),0,H6/D6)),$F6) -> 2 | H6: 4 | I6: =E6*G6 -> 4 | J6: Digital Wallet | K6: In-store | L6: 45088 | M6: =IF(OR(L6="UNKNOWN",L6="ERROR",L6=""),DATE(1900,1,1),L6) -> 45088
A7: TXN_2602893 | B7: Smoothie | C7: =IF(OR($B7="Unknown",$B7="Error",$B7=""),IFERROR(VLOOKUP($F7, '02_UnitPriceRef'!$F$3:$G$10,2,FALSE),"N/A"),$B7) -> Smoothie | D7: 5 | E7: =IF(OR($D7="ERROR",$D7="UNKNOWN",$D7=""),IFERROR(H7/G7,0),D7) -> 5 | F7: 4 | G7: =IF(OR($F7="ERROR",$F7="UNKNOWN",$F7=""),IFERROR(VLOOKUP($C7,'02_UnitPriceRef'!$E$3:$F$10,2,0),IF(OR($D7="Error",$D7="UNKNOWN",$D7=""),0,H7/D7)),$F7) -> 4 | H7: 20 | I7: =E7*G7 -> 20 | J7: Credit Card | K7: N/A | L7: 45016 | M7: =IF(OR(L7="UNKNOWN",L7="ERROR",L7=""),DATE(1900,1,1),L7) -> 45016
A8: TXN_4433211 | B8: UNKNOWN | C8: =IF(OR($B8="Unknown",$B8="Error",$B8=""),IFERROR(VLOOKUP($F8, '02_UnitPriceRef'!$F$3:$G$10,2,FALSE),"N/A"),$B8) -> Cake | D8: 3 | E8: =IF(OR($D8="ERROR",$D8="UNKNOWN",$D8=""),IFERROR(H8/G8,0),D8) -> 3 | F8: 3 | G8: =IF(OR($F8="ERROR",$F8="UNKNOWN",$F8=""),IFERROR(VLOOKUP($C8,'02_UnitPriceRef'!$E$3:$F$10,2,0),IF(OR($D8="Error",$D8="UNKNOWN",$D8=""),0,H8/D8)),$F8) -> 3 | H8: 9 | I8: =E8*G8 -> 9 | J8: N/A | K8: Takeaway | L8: 45205 | M8: =IF(OR(L8="UNKNOWN",L8="ERROR",L8=""),DATE(1900,1,1),L8) -> 45205
A9: TXN_6699534 | B9: Sandwich | C9: =IF(OR($B9="Unknown",$B9="Error",$B9=""),IFERROR(VLOOKUP($F9, '02_UnitPriceRef'!$F$3:$G$10,2,FALSE),"N/A"),$B9) -> Sandwich | D9: 4 | E9: =IF(OR($D9="ERROR",$D9="UNKNOWN",$D9=""),IFERROR(H9/G9,0),D9) -> 4 | F9: 4 | G9: =IF(OR($F9="ERROR",$F9="UNKNOWN",$F9=""),IFERROR(VLOOKUP($C9,'02_UnitPriceRef'!$E$3:$F$10,2,0),IF(OR($D9="Error",$D9="UNKNOWN",$D9=""),0,H9/D9)),$F9) -> 4 | H9: 16 | I9: =E9*G9 -> 16 | J9: Cash | K9: N/A | L9: 45227 | M9: =IF(OR(L9="UNKNOWN",L9="ERROR",L9=""),DATE(1900,1,1),L9) -> 45227
A10: TXN_4717867 | C10: =IF(OR($B10="Unknown",$B10="Error",$B10=""),IFERROR(VLOOKUP($F10, '02_UnitPriceRef'!$F$3:$G$10,2,FALSE),"N/A"),$B10) -> Cake | D10: 5 | E10: =IF(OR($D10="ERROR",$D10="UNKNOWN",$D10=""),IFERROR(H10/G10,0),D10) -> 5 | F10: 3 | G10: =IF(OR($F10="ERROR",$F10="UNKNOWN",$F10=""),IFERROR(VLOOKUP($C10,'02_UnitPriceRef'!$E$3:$F$10,2,0),IF(OR($D10="Error",$D10="UNKNOWN",$D10=""),0,H10/D10)),$F10) -> 3 | H10: 15 | I10: =E10*G10 -> 15 | J10: N/A | K10: Takeaway | L10: 45135 | M10: =IF(OR(L10="UNKNOWN",L10="ERROR",L10=""),DATE(1900,1,1),L10) -> 45135
A11: TXN_2064365 | B11: Sandwich | C11: =IF(OR($B11="Unknown",$B11="Error",$B11=""),IFERROR(VLOOKUP($F11, '02_UnitPriceRef'!$F$3:$G$10,2,FALSE),"N/A"),$B11) -> Sandwich | D11: 5 | E11: =IF(OR($D11="ERROR",$D11="UNKNOWN",$D11=""),IFERROR(H11/G11,0),D11) -> 5 | F11: 4 | G11: =IF(OR($F11="ERROR",$F11="UNKNOWN",$F11=""),IFERROR(VLOOKUP($C11,'02_UnitPriceRef'!$E$3:$F$10,2,0),IF(OR($D11="Error",$D11="UNKNOWN",$D11=""),0,H11/D11)),$F11) -> 4 | H11: 20 | I11: =E11*G11 -> 20 | J11: N/A | K11: In-store | L11: 45291 | M11: =IF(OR(L11="UNKNOWN",L11="ERROR",L11=""),DATE(1900,1,1),L11) -> 45291
A12: TXN_2548360 | B12: Salad | C12: =IF(OR($B12="Unknown",$B12="Error",$B12=""),IFERROR(VLOOKUP($F12, '02_UnitPriceRef'!$F$3:$G$10,2,FALSE),"N/A"),$B12) -> Salad | D12: 5 | E12: =IF(OR($D12="ERROR",$D12="UNKNOWN",$D12=""),IFERROR(H12/G12,0),D12) -> 5 | F12: 5 | G12: =IF(OR($F12="ERROR",$F12="UNKNOWN",$F12=""),IFERROR(VLOOKUP($C12,'02_UnitPriceRef'!$E$3:$F$10,2,0),IF(OR($D12="Error",$D12="UNKNOWN",$D12=""),0,H12/D12)),$F12) -> 5 | H12: 25 | I12: =E12*G12 -> 25 | J12: Cash | K12: Takeaway | L12: 45237 | M12: =IF(OR(L12="UNKNOWN",L12="ERROR",L12=""),DATE(1900,1,1),L12) -> 45237
A13: TXN_3051279 | B13: Sandwich | C13: =IF(OR($B13="Unknown",$B13="Error",$B13=""),IFERROR(VLOOKUP($F13, '02_UnitPriceRef'!$F$3:$G$10,2,FALSE),"N/A"),$B13) -> Sandwich | D13: 2 | E13: =IF(OR($D13="ERROR",$D13="UNKNOWN",$D13=""),IFERROR(H13/G13,0),D13) -> 2 | F13: 4 | G13: =IF(OR($F13="ERROR",$F13="UNKNOWN",$F13=""),IFERROR(VLOOKUP($C13,'02_UnitPriceRef'!$E$3:$F$10,2,0),IF(OR($D13="Error",$D13="UNKNOWN",$D13=""),0,H13/D13)),$F13) -> 4 | H13: 8 | I13: =E13*G13 -> 8 | J13: Credit Card | K13: Takeaway | L13: ERROR | M13: =IF(OR(L13="UNKNOWN",L13="ERROR",L13=""),DATE(1900,1,1),L13) -> 1
A14: TXN_7619095 | B14: Sandwich | C14: =IF(OR($B14="Unknown",$B14="Error",$B14=""),IFERROR(VLOOKUP($F14, '02_UnitPriceRef'!$F$3:$G$10,2,FALSE),"N/A"),$B14) -> Sandwich | D14: 2 | E14: =IF(OR($D14="ERROR",$D14="UNKNOWN",$D14=""),IFERROR(H14/G14,0),D14) -> 2 | F14: 4 | G14: =IF(OR($F14="ERROR",$F14="UNKNOWN",$F14=""),IFERROR(VLOOKUP($C14,'02_UnitPriceRef'!$E$3:$F$10,2,0),IF(OR($D14="Error",$D14="UNKNOWN",$D14=""),0,H14/D14)),$F14) -> 4 | H14: 8 | I14: =E14*G14 -> 8 | J14: Cash | K14: In-store | L14: 45049 | M14: =IF(OR(L14="UNKNOWN",L14="ERROR",L14=""),DATE(1900,1,1),L14) -> 45049
A15: TXN_9437049 | B15: Cookie | C15: =IF(OR($B15="Unknown",$B15="Error",$B15=""),IFERROR(VLOOKUP($F15, '02_UnitPriceRef'!$F$3:$G$10,2,FALSE),"N/A"),$B15) -> Cookie | D15: 5 | E15: =IF(OR($D15="ERROR",$D15="UNKNOWN",$D15=""),IFERROR(H15/G15,0),D15) -> 5 | F15: 1 | G15: =IF(OR($F15="ERROR",$F15="UNKNOWN",$F15=""),IFERROR(VLOOKUP($C15,'02_UnitPriceRef'!$E$3:$F$10,2,0),IF(OR($D15="Error",$D15="UNKNOWN",$D15=""),0,H15/D15)),$F15) -> 1 | H15: 5 | I15: =E15*G15 -> 5 | J15: N/A | K15: Takeaway | L15: 45078 | M15: =IF(OR(L15="UNKNOWN",L15="ERROR",L15=""),DATE(1900,1,1),L15) -> 45078
A16: TXN_8915701 | B16: ERROR | C16: =IF(OR($B16="Unknown",$B16="Error",$B16=""),IFERROR(VLOOKUP($F16, '02_UnitPriceRef'!$F$3:$G$10,2,FALSE),"N/A"),$B16) -> Tea | D16: 2 | E16: =IF(OR($D16="ERROR",$D16="UNKNOWN",$D16=""),IFERROR(H16/G16,0),D16) -> 2 | F16: 1.5 | G16: =IF(OR($F16="ERROR",$F16="UNKNOWN",$F16=""),IFERROR(VLOOKUP($C16,'02_UnitPriceRef'!$E$3:$F$10,2,0),IF(OR($D16="Error",$D16="UNKNOWN",$D16=""),0,H16/D16)),$F16) -> 1.5 | H16: 3 | I16: =E16*G16 -> 3 | J16: N/A | K16: In-store | L16: 45006 | M16: =IF(OR(L16="UNKNOWN",L16="ERROR",L16=""),DATE(1900,1,1),L16) -> 45006
A17: TXN_2847255 | B17: Salad | C17: =IF(OR($B17="Unknown",$B17="Error",$B17=""),IFERROR(VLOOKUP($F17, '02_UnitPriceRef'!$F$3:$G$10,2,FALSE),"N/A"),$B17) -> Salad | D17: 3 | E17: =IF(OR($D17="ERROR",$D17="UNKNOWN",$D17=""),IFERROR(H17/G17,0),D17) -> 3 | F17: 5 | G17: =IF(OR($F17="ERROR",$F17="UNKNOWN",$F17=""),IFERROR(VLOOKUP($C17,'02_UnitPriceRef'!$E$3:$F$10,2,0),IF(OR($D17="Error",$D17="UNKNOWN",$D17=""),0,H17/D17)),$F17) -> 5 | H17: 15 | I17: =E17*G17 -> 15 | J17: Credit Card | K17: In-store | L17: 45245 | M17: =IF(OR(L17="UNKNOWN",L17="ERROR",L17=""),DATE(1900,1,1),L17) -> 45245
A18: TXN_3765707 | B18: Sandwich | C18: =IF(OR($B18="Unknown",$B18="Error",$B18=""),IFERROR(VLOOKUP($F18, '02_UnitPriceRef'!$F$3:$G$10,2,FALSE),"N/A"),$B18) -> Sandwich | D18: 1 | E18: =IF(OR($D18="ERROR",$D18="UNKNOWN",$D18=""),IFERROR(H18/G18,0),D18) -> 1 | F18: 4 | G18: =IF(OR($F18="ERROR",$F18="UNKNOWN",$F18=""),IFERROR(VLOOKUP($C18,'02_UnitPriceRef'!$E$3:$F$10,2,0),IF(OR($D18="Error",$D18="UNKNOWN",$D18=""),0,H18/D18)),$F18) -> 4 | H18: 4 | I18: =E18*G18 -> 4 | J18: N/A | K18: N/A | L18: 45087 | M18: =IF(OR(L18="UNKNOWN",L18="ERROR",L18=""),DATE(1900,1,1),L18) -> 45087
A19: TXN_6769710 | B19: Juice | C19: =IF(OR($B19="Unknown",$B19="Error",$B19=""),IFERROR(VLOOKUP($F19, '02_UnitPriceRef'!$F$3:$G$10,2,FALSE),"N/A"),$B19) -> Juice | D19: 2 | E19: =IF(OR($D19="ERROR",$D19="UNKNOWN",$D19=""),IFERROR(H19/G19,0),D19) -> 2 | F19: 3 | G19: =IF(OR($F19="ERROR",$F19="UNKNOWN",$F19=""),IFERROR(VLOOKUP($C19,'02_UnitPriceRef'!$E$3:$F$10,2,0),IF(OR($D19="Error",$D19="UNKNOWN",$D19=""),0,H19/D19)),$F19) -> 3 | H19: 6 | I19: =E19*G19 -> 6 | J19: Cash | K19: In-store | L19: 44981 | M19: =IF(OR(L19="UNKNOWN",L19="ERROR",L19=""),DATE(1900,1,1),L19) -> 44981
A20: TXN_8876618 | B20: Cake | C20: =IF(OR($B20="Unknown",$B20="Error",$B20=""),IFERROR(VLOOKUP($F20, '02_UnitPriceRef'!$F$3:$G$10,2,FALSE),"N/A"),$B20) -> Cake | D20: 5 | E20: =IF(OR($D20="ERROR",$D20="UNKNOWN",$D20=""),IFERROR(H20/G20,0),D20) -> 5 | F20: 3 | G20: =IF(OR($F20="ERROR",$F20="UNKNOWN",$F20=""),IFERROR(VLOOKUP($C20,'02_UnitPriceRef'!$E$3:$F$10,2,0),IF(OR($D20="Error",$D20="UNKNOWN",$D20=""),0,H20/D20)),$F20) -> 3 | H20: 15 | I20: =E20*G20 -> 15 | J20: Cash | K20: N/A | L20: 45010 | M20: =IF(OR(L20="UNKNOWN",L20="ERROR",L20=""),DATE(1900,1,1),L20) -> 45010
A21: TXN_3709394 | B21: Juice | C21: =IF(OR($B21="Unknown",$B21="Error",$B21=""),IFERROR(VLOOKUP($F21, '02_UnitPriceRef'!$F$3:$G$10,2,FALSE),"N/A"),$B21) -> Juice | D21: 4 | E21: =IF(OR($D21="ERROR",$D21="UNKNOWN",$D21=""),IFERROR(H21/G21,0),D21) -> 4 | F21: 3 | G21: =IF(OR($F21="ERROR",$F21="UNKNOWN",$F21=""),IFERROR(VLOOKUP($C21,'02_UnitPriceRef'!$E$3:$F$10,2,0),IF(OR($D21="Error",$D21="UNKNOWN",$D21=""),0,H21/D21)),$F21) -> 3 | H21: 12 | I21: =E21*G21 -> 12 | J21: Cash | K21: Takeaway | L21: 44941 | M21: =IF(OR(L21="UNKNOWN",L21="ERROR",L21=""),DATE(1900,1,1),L21) -> 44941
A22: TXN_3522028 | B22: Smoothie | C22: =IF(OR($B22="Unknown",$B22="Error",$B22=""),IFERROR(VLOOKUP($F22, '02_UnitPriceRef'!$F$3:$G$10,2,FALSE),"N/A"),$B22) -> Smoothie | D22: ERROR | E22: =IF(OR($D22="ERROR",$D22="UNKNOWN",$D22=""),IFERROR(H22/G22,0),D22) -> 5 | F22: 4 | G22: =IF(OR($F22="ERROR",$F22="UNKNOWN",$F22=""),IFERROR(VLOOKUP($C22,'02_UnitPriceRef'!$E$3:$F$10,2,0),IF(OR($D22="Error",$D22="UNKNOWN",$D22=""),0,H22/D22)),$F22) -> 4 | H22: 20 | I22: =E22*G22 -> 20 | J22: Cash | K22: In-store | L22: 45020 | M22: =IF(OR(L22="UNKNOWN",L22="ERROR",L22=""),DATE(1900,1,1),L22) -> 45020
A23: TXN_3567645 | B23: Smoothie | C23: =IF(OR($B23="Unknown",$B23="Error",$B23=""),IFERROR(VLOOKUP($F23, '02_UnitPriceRef'!$F$3:$G$10,2,FALSE),"N/A"),$B23) -> Smoothie | D23: 4 | E23: =IF(OR($D23="ERROR",$D23="UNKNOWN",$D23=""),IFERROR(H23/G23,0),D23) -> 4 | F23: 4 | G23: =IF(OR($F23="ERROR",$F23="UNKNOWN",$F23=""),IFERROR(VLOOKUP($C23,'02_UnitPriceRef'!$E$3:$F$10,2,0),IF(OR($D23="Error",$D23="UNKNOWN",$D23=""),0,H23/D23)),$F23) -> 4 | H23: 16 | I23: =E23*G23 -> 16 | J23: Credit Card | K23: Takeaway | L23: 45015 | M23: =IF(OR(L23="UNKNOWN",L23="ERROR",L23=""),DATE(1900,1,1),L23) -> 45015
A24: TXN_5132361 | B24: Sandwich | C24: =IF(OR($B24="Unknown",$B24="Error",$B24=""),IFERROR(VLOOKUP($F24, '02_UnitPriceRef'!$F$3:$G$10,2,FALSE),"N/A"),$B24) -> Sandwich | D24: 3 | E24: =IF(OR($D24="ERROR",$D24="UNKNOWN",$D24=""),IFERROR(H24/G24,0),D24) -> 3 | F24: 4 | G24: =IF(OR($F24="ERROR",$F24="UNKNOWN",$F24=""),IFERROR(VLOOKUP($C24,'02_UnitPriceRef'!$E$3:$F$10,2,0),IF(OR($D24="Error",$D24="UNKNOWN",$D24=""),0,H24/D24)),$F24) -> 4 | H24: 12 | I24: =E24*G24 -> 12 | J24: Digital Wallet | K24: Takeaway | L24: 45261 | M24: =IF(OR(L24="UNKNOWN",L24="ERROR",L24=""),DATE(1900,1,1),L24) -> 45261
A25: TXN_2616390 | B25: Sandwich | C25: =IF(OR($B25="Unknown",$B25="Error",$B25=""),IFERROR(VLOOKUP($F25, '02_UnitPriceRef'!$F$3:$G$10,2,FALSE),"N/A"),$B25) -> Sandwich | D25: 2 | E25: =IF(OR($D25="ERROR",$D25="UNKNOWN",$D25=""),IFERROR(H25/G25,0),D25) -> 2 | F25: 4 | G25: =IF(OR($F25="ERROR",$F25="UNKNOWN",$F25=""),IFERROR(VLOOKUP($C25,'02_UnitPriceRef'!$E$3:$F$10,2,0),IF(OR($D25="Error",$D25="UNKNOWN",$D25=""),0,H25/D25)),$F25) -> 4 | H25: 8 | I25: =E25*G25 -> 8 | J25: N/A | K25: N/A | L25: 45187 | M25: =IF(OR(L25="UNKNOWN",L25="ERROR",L25=""),DATE(1900,1,1),L25) -> 45187
A26: TXN_9400181 | B26: Sandwich | C26: =IF(OR($B26="Unknown",$B26="Error",$B26=""),IFERROR(VLOOKUP($F26, '02_UnitPriceRef'!$F$3:$G$10,2,FALSE),"N/A"),$B26) -> Sandwich | D26: 5 | E26: =IF(OR($D26="ERROR",$D26="UNKNOWN",$D26=""),IFERROR(H26/G26,0),D26) -> 5 | F26: 4 | G26: =IF(OR($F26="ERROR",$F26="UNKNOWN",$F26=""),IFERROR(VLOOKUP($C26,'02_UnitPriceRef'!$E$3:$F$10,2,0),IF(OR($D26="Error",$D26="UNKNOWN",$D26=""),0,H26/D26)),$F26) -> 4 | H26: 20 | I26: =E26*G26 -> 20 | J26: Cash | K26: In-store | L26: 45080 | M26: =IF(OR(L26="UNKNOWN",L26="ERROR",L26=""),DATE(1900,1,1),L26) -> 45080
A27: TXN_7958992 | B27: Smoothie | C27: =IF(OR($B27="Unknown",$B27="Error",$B27=""),IFERROR(VLOOKUP($F27, '02_UnitPriceRef'!$F$3:$G$10,2,FALSE),"N/A"),$B27) -> Smoothie | D27: 3 | E27: =IF(OR($D27="ERROR",$D27="UNKNOWN",$D27=""),IFERROR(H27/G27,0),D27) -> 3 | F27: 4 | G27: =IF(OR($F27="ERROR",$F27="UNKNOWN",$F27=""),IFERROR(VLOOKUP($C27,'02_UnitPriceRef'!$E$3:$F$10,2,0),IF(OR($D27="Error",$D27="UNKNOWN",$D27=""),0,H27/D27)),$F27) -> 4 | I27: =E27*G27 -> 12 | J27: N/A | K27: N/A | L27: 45273 | M27: =IF(OR(L27="UNKNOWN",L27="ERROR",L27=""),DATE(1900,1,1),L27) -> 45273
A28: TXN_5183041 | B28: Cookie | C28: =IF(OR($B28="Unknown",$B28="Error",$B28=""),IFERROR(VLOOKUP($F28, '02_UnitPriceRef'!$F$3:$G$10,2,FALSE),"N/A"),$B28) -> Cookie | D28: 5 | E28: =IF(OR($D28="ERROR",$D28="UNKNOWN",$D28=""),IFERROR(H28/G28,0),D28) -> 5 | F28: 1 | G28: =IF(OR($F28="ERROR",$F28="UNKNOWN",$F28=""),IFERROR(VLOOKUP($C28,'02_UnitPriceRef'!$E$3:$F$10,2,0),IF(OR($D28="Error",$D28="UNKNOWN",$D28=""),0,H28/D28)),$F28) -> 1 | H28: 5 | I28: =E28*G28 -> 5 | J28: Credit Card | K28: In-store | L28: 45036 | M28: =IF(OR(L28="UNKNOWN",L28="ERROR",L28=""),DATE(1900,1,1),L28) -> 45036
A29: TXN_5695074 | B29: Juice | C29: =IF(OR($B29="Unknown",$B29="Error",$B29=""),IFERROR(VLOOKUP($F29, '02_UnitPriceRef'!$F$3:$G$10,2,FALSE),"N/A"),$B29) -> Juice | D29: 4 | E29: =IF(OR($D29="ERROR",$D29="UNKNOWN",$D29=""),IFERROR(H29/G29,0),D29) -> 4 | F29: 3 | G29: =IF(OR($F29="ERROR",$F29="UNKNOWN",$F29=""),IFERROR(VLOOKUP($C29,'02_UnitPriceRef'!$E$3:$F$10,2,0),IF(OR($D29="Error",$D29="UNKNOWN",$D29=""),0,H29/D29)),$F29) -> 3 | H29: 12 | I29: =E29*G29 -> 12 | J29: Credit Card | K29: Takeaway | L29: 45026 | M29: =IF(OR(L29="UNKNOWN",L29="ERROR",L29=""),DATE(1900,1,1),L29) -> 45026
A30: TXN_8467949 | B30: Smoothie | C30: =IF(OR($B30="Unknown",$B30="Error",$B30=""),IFERROR(VLOOKUP($F30, '02_UnitPriceRef'!$F$3:$G$10,2,FALSE),"N/A"),$B30) -> Smoothie | D30: 5 | E30: =IF(OR($D30="ERROR",$D30="UNKNOWN",$D30=""),IFERROR(H30/G30,0),D30) -> 5 | F30: 4 | G30: =IF(OR($F30="ERROR",$F30="UNKNOWN",$F30=""),IFERROR(VLOOKUP($C30,'02_UnitPriceRef'!$E$3:$F$10,2,0),IF(OR($D30="Error",$D30="UNKNOWN",$D30=""),0,H30/D30)),$F30) -> 4 | H30: 20 | I30: =E30*G30 -> 20 | J30: Credit Card | K30: N/A | L30: 44996 | M30: =IF(OR(L30="UNKNOWN",L30="ERROR",L30=""),DATE(1900,1,1),L30) -> 44996
A31: TXN_7640952 | B31: Cake | C31: =IF(OR($B31="Unknown",$B31="Error",$B31=""),IFERROR(VLOOKUP($F31, '02_UnitPriceRef'!$F$3:$G$10,2,FALSE),"N/A"),$B31) -> Cake | D31: 4 | E31: =IF(OR($D31="ERROR",$D31="UNKNOWN",$D31=""),IFERROR(H31/G31,0),D31) -> 4 | F31: 3 | G31: =IF(OR($F31="ERROR",$F31="UNKNOWN",$F31=""),IFERROR(VLOOKUP($C31,'02_UnitPriceRef'!$E$3:$F$10,2,0),IF(OR($D31="Error",$D31="UNKNOWN",$D31=""),0,H31/D31)),$F31) -> 3 | H31: 12 | I31: =E31*G31 -> 12 | J31: Digital Wallet | K31: Takeaway | L31: ERROR | M31: =IF(OR(L31="UNKNOWN",L31="ERROR",L31=""),DATE(1900,1,1),L31) -> 1
A32: TXN_1736287 | C32: =IF(OR($B32="Unknown",$B32="Error",$B32=""),IFERROR(VLOOKUP($F32, '02_UnitPriceRef'!$F$3:$G$10,2,FALSE),"N/A"),$B32) -> Coffee | D32: 5 | E32: =IF(OR($D32="ERROR",$D32="UNKNOWN",$D32=""),IFERROR(H32/G32,0),D32) -> 5 | F32: 2 | G32: =IF(OR($F32="ERROR",$F32="UNKNOWN",$F32=""),IFERROR(VLOOKUP($C32,'02_UnitPriceRef'!$E$3:$F$10,2,0),IF(OR($D32="Error",$D32="UNKNOWN",$D32=""),0,H32/D32)),$F32) -> 2 | H32: 10 | I32: =E32*G32 -> 10 | J32: Digital Wallet | K32: N/A | L32: 45079 | M32: =IF(OR(L32="UNKNOWN",L32="ERROR",L32=""),DATE(1900,1,1),L32) -> 45079
A33: TXN_8927252 | B33: UNKNOWN | C33: =IF(OR($B33="Unknown",$B33="Error",$B33=""),IFERROR(VLOOKUP($F33, '02_UnitPriceRef'!$F$3:$G$10,2,FALSE),"N/A"),$B33) -> Cookie | D33: 2 | E33: =IF(OR($D33="ERROR",$D33="UNKNOWN",$D33=""),IFERROR(H33/G33,0),D33) -> 2 | F33: 1 | G33: =IF(OR($F33="ERROR",$F33="UNKNOWN",$F33=""),IFERROR(VLOOKUP($C33,'02_UnitPriceRef'!$E$3:$F$10,2,0),IF(OR($D33="Error",$D33="UNKNOWN",$D33=""),0,H33/D33)),$F33) -> 1 | H33: ERROR | I33: =E33*G33 -> 2 | J33: Credit Card | K33: N/A | L33: 45236 | M33: =IF(OR(L33="UNKNOWN",L33="ERROR",L33=""),DATE(1900,1,1),L33) -> 45236
A34: TXN_9677376 | B34: Smoothie | C34: =IF(OR($B34="Unknown",$B34="Error",$B34=""),IFERROR(VLOOKUP($F34, '02_UnitPriceRef'!$F$3:$G$10,2,FALSE),"N/A"),$B34) -> Smoothie | D34: 4 | E34: =IF(OR($D34="ERROR",$D34="UNKNOWN",$D34=""),IFERROR(H34/G34,0),D34) -> 4 | F34: 4 | G34: =IF(OR($F34="ERROR",$F34="UNKNOWN",$F34=""),IFERROR(VLOOKUP($C34,'02_UnitPriceRef'!$E$3:$F$10,2,0),IF(OR($D34="Error",$D34="UNKNOWN",$D34=""),0,H34/D34)),$F34) -> 4 | H34: 16 | I34: =E34*G34 -> 16 | J34: N/A | K34: In-store | L34: 45153 | M34: =IF(OR(L34="UNKNOWN",L34="ERROR",L34=""),DATE(1900,1,1),L34) -> 45153
A35: TXN_7710508 | B35: UNKNOWN | C35: =IF(OR($B35="Unknown",$B35="Error",$B35=""),IFERROR(VLOOKUP($F35, '02_UnitPriceRef'!$F$3:$G$10,2,FALSE),"N/A"),$B35) -> Cookie | D35: 5 | E35: =IF(OR($D35="ERROR",$D35="UNKNOWN",$D35=""),IFERROR(H35/G35,0),D35) -> 5 | F35: 1 | G35: =IF(OR($F35="ERROR",$F35="UNKNOWN",$F35=""),IFERROR(VLOOKUP($C35,'02_UnitPriceRef'!$E$3:$F$10,2,0),IF(OR($D35="Error",$D35="UNKNOWN",$D35=""),0,H35/D35)),$F35) -> 1 | H35: 5 | I35: =E35*G35 -> 5 | J35: Cash | K35: N/A | L35: ERROR | M35: =IF(OR(L35="UNKNOWN",L35="ERROR",L35=""),DATE(1900,1,1),L35) -> 1
A36: TXN_8853997 | B36: Smoothie | C36: =IF(OR($B36="Unknown",$B36="Error",$B36=""),IFERROR(VLOOKUP($F36, '02_UnitPriceRef'!$F$3:$G$10,2,FALSE),"N/A"),$B36) -> Smoothie | D36: 2 | E36: =IF(OR($D36="ERROR",$D36="UNKNOWN",$D36=""),IFERROR(H36/G36,0),D36) -> 2 | F36: 4 | G36: =IF(OR($F36="ERROR",$F36="UNKNOWN",$F36=""),IFERROR(VLOOKUP($C36,'02_UnitPriceRef'!$E$3:$F$10,2,0),IF(OR($D36="Error",$D36="UNKNOWN",$D36=""),0,H36/D36)),$F36) -> 4 | H36: 8 | I36: =E36*G36 -> 8 | J36: Digital Wallet | K36: Takeaway | L36: 45208 | M36: =IF(OR(L36="UNKNOWN",L36="ERROR",L36=""),DATE(1900,1,1),L36) -> 45208
A37: TXN_9130559 | B37: Sandwich | C37: =IF(OR($B37="Unknown",$B37="Error",$B37=""),IFERROR(VLOOKUP($F37, '02_UnitPriceRef'!$F$3:$G$10,2,FALSE),"N/A"),$B37) -> Sandwich | D37: 1 | E37: =IF(OR($D37="ERROR",$D37="UNKNOWN",$D37=""),IFERROR(H37/G37,0),D37) -> 1 | F37: 4 | G37: =IF(OR($F37="ERROR",$F37="UNKNOWN",$F37=""),IFERROR(VLOOKUP($C37,'02_UnitPriceRef'!$E$3:$F$10,2,0),IF(OR($D37="Error",$D37="UNKNOWN",$D37=""),0,H37/D37)),$F37) -> 4 | H37: 4 | I37: =E37*G37 -> 4 | J37: Credit Card | K37: N/A | L37: 45074 | M37: =IF(OR(L37="UNKNOWN",L37="ERROR",L37=""),DATE(1900,1,1),L37) -> 45074
A38: TXN_6855453 | B38: UNKNOWN | C38: =IF(OR($B38="Unknown",$B38="Error",$B38=""),IFERROR(VLOOKUP($F38, '02_UnitPriceRef'!$F$3:$G$10,2,FALSE),"N/A"),$B38) -> Cake | D38: 4 | E38: =IF(OR($D38="ERROR",$D38="UNKNOWN",$D38=""),IFERROR(H38/G38,0),D38) -> 4 | F38: 3 | G38: =IF(OR($F38="ERROR",$F38="UNKNOWN",$F38=""),IFERROR(VLOOKUP($C38,'02_UnitPriceRef'!$E$3:$F$10,2,0),IF(OR($D38="Error",$D38="UNKNOWN",$D38=""),0,H38/D38)),$F38) -> 3 | H38: 12 | I38: =E38*G38 -> 12 | J38: N/A | K38: In-store | L38: 45124 | M38: =IF(OR(L38="UNKNOWN",L38="ERROR",L38=""),DATE(1900,1,1),L38) -> 45124
A39: TXN_1080432 | B39: Salad | C39: =IF(OR($B39="Unknown",$B39="Error",$B39=""),IFERROR(VLOOKUP($F39, '02_UnitPriceRef'!$F$3:$G$10,2,FALSE),"N/A"),$B39) -> Salad | D39: 2 | E39: =IF(OR($D39="ERROR",$D39="UNKNOWN",$D39=""),IFERROR(H39/G39,0),D39) -> 2 | F39: 5 | G39: =IF(OR($F39="ERROR",$F39="UNKNOWN",$F39=""),IFERROR(VLOOKUP($C39,'02_UnitPriceRef'!$E$3:$F$10,2,0),IF(OR($D39="Error",$D39="UNKNOWN",$D39=""),0,H39/D39)),$F39) -> 5 | H39: 10 | I39: =E39*G39 -> 10 | J39: Credit Card | K39: In-store | L39: 45045 | M39: =IF(OR(L39="UNKNOWN",L39="ERROR",L39=""),DATE(1900,1,1),L39) -> 45045
A40: TXN_2655815 | B40: Smoothie | C40: =IF(OR($B40="Unknown",$B40="Error",$B40=""),IFERROR(VLOOKUP($F40, '02_UnitPriceRef'!$F$3:$G$10,2,FALSE),"N/A"),$B40) -> Smoothie | D40: 4 | E40: =IF(OR($D40="ERROR",$D40="UNKNOWN",$D40=""),IFERROR(H40/G40,0),D40) -> 4 | F40: 4 | G40: =IF(OR($F40="ERROR",$F40="UNKNOWN",$F40=""),IFERROR(VLOOKUP($C40,'02_UnitPriceRef'!$E$3:$F$10,2,0),IF(OR($D40="Error",$D40="UNKNOWN",$D40=""),0,H40/D40)),$F40) -> 4 | H40: 16 | I40: =E40*G40 -> 16 | J40: N/A | K40: Takeaway | L40: 45085 | M40: =IF(OR(L40="UNKNOWN",L40="ERROR",L40=""),DATE(1900,1,1),L40) -> 45085
...

Sheet 02_UnitPriceRef
A1: Cleaned_Item | B1: Price Per Unit
A2: Cake | B2: 3 | E2: Unique_Item | F2: Price Per Unit
B3: (blank) | E3: Cake | F3: 3 | G3: Cake
A4: Cake Total | E4: Coffee | F4: 2 | G4: Coffee
A5: Coffee | B5: 2 | E5: Cookie | F5: 1 | G5: Cookie
B6: (blank) | E6: Juice | F6: 3 | G6: Juice
A7: Coffee Total | E7: Salad | F7: 5 | G7: Salad
A8: Cookie | B8: 1 | E8: Sandwich | F8: 4 | G8: Sandwich/Smoothie
B9: (blank) | E9: Smoothie | F9: 4 | G9: Sandwich/Smoothie
A10: Cookie Total | E10: Tea | F10: 1.5 | G10: Tea
A11: Juice | B11: 3
B12: (blank)
A13: Juice Total
A14: N/A | B14: (blank)
A15: N/A Total
A16: Salad | B16: 5
B17: (blank)
A18: Salad Total
A19: Sandwich | B19: 4
B20: (blank)
A21: Sandwich Total
A22: Sandwich/Smoothie | B22: 4
A23: Sandwich/Smoothie Total
A24: Smoothie | B24: 4
B25: (blank)
A26: Smoothie Total
A27: Tea | B27: 1.5
B28: (blank)
A29: Tea Total

Sheet 01_Raw_Data
A1: Transaction ID | B1: Item | C1: Quantity | D1: Price Per Unit | E1: Total Spent | F1: Payment Method | G1: Location | H1: Transaction Date
A2: TXN_1961373 | B2: Coffee | C2: 2 | D2: 2 | E2: 4 | F2: Credit Card | G2: Takeaway | H2: 45177
A3: TXN_4977031 | B3: Cake | C3: 4 | D3: 3 | E3: 12 | F3: Cash | G3: In-store | H3: 45062
A4: TXN_4271903 | B4: Cookie | C4: 4 | D4: 1 | E4: ERROR | F4: Credit Card | G4: In-store | H4: 45126
A5: TXN_7034554 | B5: Salad | C5: 2 | D5: 5 | E5: 10 | F5: UNKNOWN | G5: UNKNOWN | H5: 45043
A6: TXN_3160411 | B6: Coffee | C6: 2 | D6: 2 | E6: 4 | F6: Digital Wallet | G6: In-store | H6: 45088
A7: TXN_2602893 | B7: Smoothie | C7: 5 | D7: 4 | E7: 20 | F7: Credit Card | H7: 45016
A8: TXN_4433211 | B8: UNKNOWN | C8: 3 | D8: 3 | E8: 9 | F8: ERROR | G8: Takeaway | H8: 45205
A9: TXN_6699534 | B9: Sandwich | C9: 4 | D9: 4 | E9: 16 | F9: Cash | G9: UNKNOWN | H9: 45227
A10: TXN_4717867 | C10: 5 | D10: 3 | E10: 15 | G10: Takeaway | H10: 45135
A11: TXN_2064365 | B11: Sandwich | C11: 5 | D11: 4 | E11: 20 | G11: In-store | H11: 45291
A12: TXN_2548360 | B12: Salad | C12: 5 | D12: 5 | E12: 25 | F12: Cash | G12: Takeaway | H12: 45237
A13: TXN_3051279 | B13: Sandwich | C13: 2 | D13: 4 | E13: 8 | F13: Credit Card | G13: Takeaway | H13: ERROR
A14: TXN_7619095 | B14: Sandwich | C14: 2 | D14: 4 | E14: 8 | F14: Cash | G14: In-store | H14: 45049
A15: TXN_9437049 | B15: Cookie | C15: 5 | D15: 1 | E15: 5 | G15: Takeaway | H15: 45078
A16: TXN_8915701 | B16: ERROR | C16: 2 | D16: 1.5 | E16: 3 | G16: In-store | H16: 45006
A17: TXN_2847255 | B17: Salad | C17: 3 | D17: 5 | E17: 15 | F17: Credit Card | G17: In-store | H17: 45245
A18: TXN_3765707 | B18: Sandwich | C18: 1 | D18: 4 | E18: 4 | H18: 45087
A19: TXN_6769710 | B19: Juice | C19: 2 | D19: 3 | E19: 6 | F19: Cash | G19: In-store | H19: 44981
A20: TXN_8876618 | B20: Cake | C20: 5 | D20: 3 | E20: 15 | F20: Cash | G20: ERROR | H20: 45010
A21: TXN_3709394 | B21: Juice | C21: 4 | D21: 3 | E21: 12 | F21: Cash | G21: Takeaway | H21: 44941
A22: TXN_3522028 | B22: Smoothie | C22: ERROR | D22: 4 | E22: 20 | F22: Cash | G22: In-store | H22: 45020
A23: TXN_3567645 | B23: Smoothie | C23: 4 | D23: 4 | E23: 16 | F23: Credit Card | G23: Takeaway | H23: 45015
A24: TXN_5132361 | B24: Sandwich | C24: 3 | D24: 4 | E24: 12 | F24: Digital Wallet | G24: Takeaway | H24: 45261
A25: TXN_2616390 | B25: Sandwich | C25: 2 | D25: 4 | E25: 8 | H25: 45187
A26: TXN_9400181 | B26: Sandwich | C26: 5 | D26: 4 | E26: 20 | F26: Cash | G26: In-store | H26: 45080
A27: TXN_7958992 | B27: Smoothie | C27: 3 | D27: 4 | F27: UNKNOWN | G27: UNKNOWN | H27: 45273
A28: TXN_5183041 | B28: Cookie | C28: 5 | D28: 1 | E28: 5 | F28: Credit Card | G28: In-store | H28: 45036
A29: TXN_5695074 | B29: Juice | C29: 4 | D29: 3 | E29: 12 | F29: Credit Card | G29: Takeaway | H29: 45026
A30: TXN_8467949 | B30: Smoothie | C30: 5 | D30: 4 | E30: 20 | F30: Credit Card | H30: 44996
A31: TXN_7640952 | B31: Cake | C31: 4 | D31: 3 | E31: 12 | F31: Digital Wallet | G31: Takeaway | H31: ERROR
A32: TXN_1736287 | C32: 5 | D32: 2 | E32: 10 | F32: Digital Wallet | H32: 45079
A33: TXN_8927252 | B33: UNKNOWN | C33: 2 | D33: 1 | E33: ERROR | F33: Credit Card | G33: ERROR | H33: 45236
A34: TXN_9677376 | B34: Smoothie | C34: 4 | D34: 4 | E34: 16 | G34: In-store | H34: 45153
A35: TXN_7710508 | B35: UNKNOWN | C35: 5 | D35: 1 | E35: 5 | F35: Cash | H35: ERROR
A36: TXN_8853997 | B36: Smoothie | C36: 2 | D36: 4 | E36: 8 | F36: Digital Wallet | G36: Takeaway | H36: 45208
A37: TXN_9130559 | B37: Sandwich | C37: 1 | D37: 4 | E37: 4 | F37: Credit Card | G37: UNKNOWN | H37: 45074
A38: TXN_6855453 | B38: UNKNOWN | C38: 4 | D38: 3 | E38: 12 | G38: In-store | H38: 45124
A39: TXN_1080432 | B39: Salad | C39: 2 | D39: 5 | E39: 10 | F39: Credit Card | G39: In-store | H39: 45045
A40: TXN_2655815 | B40: Smoothie | C40: 4 | D40: 4 | E40: 16 | G40: Takeaway | H40: 45085
...
