Workbook

Sheet 04_AnalyticsReady
A1: Transaction ID | B1: Item | C1: Quantity | D1: Price Per Unit | E1: Total Spent | F1: Payment Method | G1: Location | H1: Transaction Date
A2: TXN_1961373 | B2: Coffee | C2: 2 | D2: 2 | E2: 4 | F2: Credit Card | G2: Takeaway | H2: 45177
A3: TXN_4977031 | B3: Cake | C3: 4 | D3: 3 | E3: 12 | F3: Cash | G3: In-store | H3: 45062
A4: TXN_4271903 | B4: Cookie | C4: 4 | D4: 1 | E4: 4 | F4: Credit Card | G4: In-store | H4: 45126
A5: TXN_7034554 | B5: Salad | C5: 2 | D5: 5 | E5: 10 | F5: N/A | G5: N/A | H5: 45043
A6: TXN_3160411 | B6: Coffee | C6: 2 | D6: 2 | E6: 4 | F6: Digital Wallet | G6: In-store | H6: 45088
A7: TXN_2602893 | B7: Smoothie | C7: 5 | D7: 4 | E7: 20 | F7: Credit Card | G7: N/A | H7: 45016
A8: TXN_4433211 | B8: Cake/Juice | C8: 3 | D8: 3 | E8: 9 | F8: N/A | G8: Takeaway | H8: 45205
A9: TXN_6699534 | B9: Sandwich | C9: 4 | D9: 4 | E9: 16 | F9: Cash | G9: N/A | H9: 45227
A10: TXN_4717867 | B10: Cake/Juice | C10: 5 | D10: 3 | E10: 15 | F10: N/A | G10: Takeaway | H10: 45135
A11: TXN_2064365 | B11: Sandwich | C11: 5 | D11: 4 | E11: 20 | F11: N/A | G11: In-store | H11: 45291
A12: TXN_2548360 | B12: Salad | C12: 5 | D12: 5 | E12: 25 | F12: Cash | G12: Takeaway | H12: 45237
A13: TXN_3051279 | B13: Sandwich | C13: 2 | D13: 4 | E13: 8 | F13: Credit Card | G13: Takeaway | H13: 2
... A10001: TXN_6170729 | B10001: Sandwich | C10001: 3 | D10001: 4 | E10001: 12 | F10001: Cash | G10001: In-store | H10001: 45237

Sheet 03_CleaningFlow
A1: Transaction ID | B1: Item | C1: Cleaned_Item 1 | D1: Cleaned_Item 2 | E1: Quantity | F1: Cleaned_Quantity | G1: Price Per Unit | H1: Cleaned_PPU | I1: Total Spent | J1: Cleaned_Total Spent | K1: Cleaned_Payment Method | L1: Cleaned_Location | M1: Transaction Date | N1: Cleaned_Transaction Date
A2: TXN_1961373 | B2: Coffee | C2: =IF(OR($B2="Unknown",$B2="Error",$B2=""),IFERROR(VLOOKUP($H2, '02_UnitPriceRef'!$F$3:$G$10,2,FALSE),"N/A"),$B2) -> Coffee | D2: Coffee | E2: 2 | F2: =IF(OR($E2="ERROR",$E2="UNKNOWN",$E2=""),IFERROR(I2/H2,0),E2) -> 2 | G2: 2 | H2: =IF(OR($G2="ERROR",$G2="UNKNOWN",$G2=""),IFERROR(VLOOKUP($D2,'02_UnitPriceRef'!$E$3:$F$10,2,0),IF(OR($E2="Error",$E2="UNKNOWN",$E2=""),0,I2/E2)),$G2) -> 2 | I2: 4 | J2: =F2*H2 -> 4 | K2: Credit Card | L2: Takeaway | M2: 45177 | N2: =IF(OR(M2="UNKNOWN",M2="ERROR",M2=""),DATE(1900,1,1),M2) -> 45177
A3: TXN_4977031 | B3: Cake | C3: =IF(OR($B3="Unknown",$B3="Error",$B3=""),IFERROR(VLOOKUP($H3, '02_UnitPriceRef'!$F$3:$G$10,2,FALSE),"N/A"),$B3) -> Cake | D3: Cake | E3: 4 | F3: =IF(OR($E3="ERROR",$E3="UNKNOWN",$E3=""),IFERROR(I3/H3,0),E3) -> 4 | G3: 3 | H3: =IF(OR($G3="ERROR",$G3="UNKNOWN",$G3=""),IFERROR(VLOOKUP($D3,'02_UnitPriceRef'!$E$3:$F$10,2,0),IF(OR($E3="Error",$E3="UNKNOWN",$E3=""),0,I3/E3)),$G3) -> 3 | I3: 12 | J3: =F3*H3 -> 12 | K3: Cash | L3: In-store | M3: 45062 | N3: =IF(OR(M3="UNKNOWN",M3="ERROR",M3=""),DATE(1900,1,1),M3) -> 45062
A4: TXN_4271903 | B4: Cookie | C4: =IF(OR($B4="Unknown",$B4="Error",$B4=""),IFERROR(VLOOKUP($H4, '02_UnitPriceRef'!$F$3:$G$10,2,FALSE),"N/A"),$B4) -> Cookie | D4: Cookie | E4: 4 | F4: =IF(OR($E4="ERROR",$E4="UNKNOWN",$E4=""),IFERROR(I4/H4,0),E4) -> 4 | G4: 1 | H4: =IF(OR($G4="ERROR",$G4="UNKNOWN",$G4=""),IFERROR(VLOOKUP($D4,'02_UnitPriceRef'!$E$3:$F$10,2,0),IF(OR($E4="Error",$E4="UNKNOWN",$E4=""),0,I4/E4)),$G4) -> 1 | I4: ERROR | J4: =F4*H4 -> 4 | K4: Credit Card | L4: In-store | M4: 45126 | N4: =IF(OR(M4="UNKNOWN",M4="ERROR",M4=""),DATE(1900,1,1),M4) -> 45126
A5: TXN_7034554 | B5: Salad | C5: =IF(OR($B5="Unknown",$B5="Error",$B5=""),IFERROR(VLOOKUP($H5, '02_UnitPriceRef'!$F$3:$G$10,2,FALSE),"N/A"),$B5) -> Salad | D5: Salad | E5: 2 | F5: =IF(OR($E5="ERROR",$E5="UNKNOWN",$E5=""),IFERROR(I5/H5,0),E5) -> 2 | G5: 5 | H5: =IF(OR($G5="ERROR",$G5="UNKNOWN",$G5=""),IFERROR(VLOOKUP($D5,'02_UnitPriceRef'!$E$3:$F$10,2,0),IF(OR($E5="Error",$E5="UNKNOWN",$E5=""),0,I5/E5)),$G5) -> 5 | I5: 10 | J5: =F5*H5 -> 10 | K5: N/A | L5: N/A | M5: 45043 | N5: =IF(OR(M5="UNKNOWN",M5="ERROR",M5=""),DATE(1900,1,1),M5) -> 45043
A6: TXN_3160411 | B6: Coffee | C6: =IF(OR($B6="Unknown",$B6="Error",$B6=""),IFERROR(VLOOKUP($H6, '02_UnitPriceRef'!$F$3:$G$10,2,FALSE),"N/A"),$B6) -> Coffee | D6: Coffee | E6: 2 | F6: =IF(OR($E6="ERROR",$E6="UNKNOWN",$E6=""),IFERROR(I6/H6,0),E6) -> 2 | G6: 2 | H6: =IF(OR($G6="ERROR",$G6="UNKNOWN",$G6=""),IFERROR(VLOOKUP($D6,'02_UnitPriceRef'!$E$3:$F$10,2,0),IF(OR($E6="Error",$E6="UNKNOWN",$E6=""),0,I6/E6)),$G6) -> 2 | I6: 4 | J6: =F6*H6 -> 4 | K6: Digital Wallet | L6: In-store | M6: 45088 | N6: =IF(OR(M6="UNKNOWN",M6="ERROR",M6=""),DATE(1900,1,1),M6) -> 45088
A7: TXN_2602893 | B7: Smoothie | C7: =IF(OR($B7="Unknown",$B7="Error",$B7=""),IFERROR(VLOOKUP($H7, '02_UnitPriceRef'!$F$3:$G$10,2,FALSE),"N/A"),$B7) -> Smoothie | D7: Smoothie | E7: 5 | F7: =IF(OR($E7="ERROR",$E7="UNKNOWN",$E7=""),IFERROR(I7/H7,0),E7) -> 5 | G7: 4 | H7: =IF(OR($G7="ERROR",$G7="UNKNOWN",$G7=""),IFERROR(VLOOKUP($D7,'02_UnitPriceRef'!$E$3:$F$10,2,0),IF(OR($E7="Error",$E7="UNKNOWN",$E7=""),0,I7/E7)),$G7) -> 4 | I7: 20 | J7: =F7*H7 -> 20 | K7: Credit Card | L7: N/A | M7: 45016 | N7: =IF(OR(M7="UNKNOWN",M7="ERROR",M7=""),DATE(1900,1,1),M7) -> 45016
A8: TXN_4433211 | B8: UNKNOWN | C8: =IF(OR($B8="Unknown",$B8="Error",$B8=""),IFERROR(VLOOKUP($H8, '02_UnitPriceRef'!$F$3:$G$10,2,FALSE),"N/A"),$B8) -> Cake/Juice | D8: Cake/Juice | E8: 3 | F8: =IF(OR($E8="ERROR",$E8="UNKNOWN",$E8=""),IFERROR(I8/H8,0),E8) -> 3 | G8: 3 | H8: =IF(OR($G8="ERROR",$G8="UNKNOWN",$G8=""),IFERROR(VLOOKUP($D8,'02_UnitPriceRef'!$E$3:$F$10,2,0),IF(OR($E8="Error",$E8="UNKNOWN",$E8=""),0,I8/E8)),$G8) -> 3 | I8: 9 | J8: =F8*H8 -> 9 | K8: N/A | L8: Takeaway | M8: 45205 | N8: =IF(OR(M8="UNKNOWN",M8="ERROR",M8=""),DATE(1900,1,1),M8) -> 45205
A9: TXN_6699534 | B9: Sandwich | C9: =IF(OR($B9="Unknown",$B9="Error",$B9=""),IFERROR(VLOOKUP($H9, '02_UnitPriceRef'!$F$3:$G$10,2,FALSE),"N/A"),$B9) -> Sandwich | D9: Sandwich | E9: 4 | F9: =IF(OR($E9="ERROR",$E9="UNKNOWN",$E9=""),IFERROR(I9/H9,0),E9) -> 4 | G9: 4 | H9: =IF(OR($G9="ERROR",$G9="UNKNOWN",$G9=""),IFERROR(VLOOKUP($D9,'02_UnitPriceRef'!$E$3:$F$10,2,0),IF(OR($E9="Error",$E9="UNKNOWN",$E9=""),0,I9/E9)),$G9) -> 4 | I9: 16 | J9: =F9*H9 -> 16 | K9: Cash | L9: N/A | M9: 45227 | N9: =IF(OR(M9="UNKNOWN",M9="ERROR",M9=""),DATE(1900,1,1),M9) -> 45227
A10: TXN_4717867 | C10: =IF(OR($B10="Unknown",$B10="Error",$B10=""),IFERROR(VLOOKUP($H10, '02_UnitPriceRef'!$F$3:$G$10,2,FALSE),"N/A"),$B10) -> Cake/Juice | D10: Cake/Juice | E10: 5 | F10: =IF(OR($E10="ERROR",$E10="UNKNOWN",$E10=""),IFERROR(I10/H10,0),E10) -> 5 | G10: 3 | H10: =IF(OR($G10="ERROR",$G10="UNKNOWN",$G10=""),IFERROR(VLOOKUP($D10,'02_UnitPriceRef'!$E$3:$F$10,2,0),IF(OR($E10="Error",$E10="UNKNOWN",$E10=""),0,I10/E10)),$G10) -> 3 | I10: 15 | J10: =F10*H10 -> 15 | K10: N/A | L10: Takeaway | M10: 45135 | N10: =IF(OR(M10="UNKNOWN",M10="ERROR",M10=""),DATE(1900,1,1),M10) -> 45135
A11: TXN_2064365 | B11: Sandwich | C11: =IF(OR($B11="Unknown",$B11="Error",$B11=""),IFERROR(VLOOKUP($H11, '02_UnitPriceRef'!$F$3:$G$10,2,FALSE),"N/A"),$B11) -> Sandwich | D11: Sandwich | E11: 5 | F11: =IF(OR($E11="ERROR",$E11="UNKNOWN",$E11=""),IFERROR(I11/H11,0),E11) -> 5 | G11: 4 | H11: =IF(OR($G11="ERROR",$G11="UNKNOWN",$G11=""),IFERROR(VLOOKUP($D11,'02_UnitPriceRef'!$E$3:$F$10,2,0),IF(OR($E11="Error",$E11="UNKNOWN",$E11=""),0,I11/E11)),$G11) -> 4 | I11: 20 | J11: =F11*H11 -> 20 | K11: N/A | L11: In-store | M11: 45291 | N11: =IF(OR(M11="UNKNOWN",M11="ERROR",M11=""),DATE(1900,1,1),M11) -> 45291
A12: TXN_2548360 | B12: Salad | C12: =IF(OR($B12="Unknown",$B12="Error",$B12=""),IFERROR(VLOOKUP($H12, '02_UnitPriceRef'!$F$3:$G$10,2,FALSE),"N/A"),$B12) -> Salad | D12: Salad | E12: 5 | F12: =IF(OR($E12="ERROR",$E12="UNKNOWN",$E12=""),IFERROR(I12/H12,0),E12) -> 5 | G12: 5 | H12: =IF(OR($G12="ERROR",$G12="UNKNOWN",$G12=""),IFERROR(VLOOKUP($D12,'02_UnitPriceRef'!$E$3:$F$10,2,0),IF(OR($E12="Error",$E12="UNKNOWN",$E12=""),0,I12/E12)),$G12) -> 5 | I12: 25 | J12: =F12*H12 -> 25 | K12: Cash | L12: Takeaway | M12: 45237 | N12: =IF(OR(M12="UNKNOWN",M12="ERROR",M12=""),DATE(1900,1,1),M12) -> 45237
A13: TXN_3051279 | B13: Sandwich | C13: =IF(OR($B13="Unknown",$B13="Error",$B13=""),IFERROR(VLOOKUP($H13, '02_UnitPriceRef'!$F$3:$G$10,2,FALSE),"N/A"),$B13) -> Sandwich | D13: Sandwich | E13: 2 | F13: =IF(OR($E13="ERROR",$E13="UNKNOWN",$E13=""),IFERROR(I13/H13,0),E13) -> 2 | G13: 4 | H13: =IF(OR($G13="ERROR",$G13="UNKNOWN",$G13=""),IFERROR(VLOOKUP($D13,'02_UnitPriceRef'!$E$3:$F$10,2,0),IF(OR($E13="Error",$E13="UNKNOWN",$E13=""),0,I13/E13)),$G13) -> 4 | I13: 8 | J13: =F13*H13 -> 8 | K13: Credit Card | L13: Takeaway | M13: ERROR | N13: =IF(OR(M13="UNKNOWN",M13="ERROR",M13=""),DATE(1900,1,1),M13) -> 1
A14: TXN_7619095 | B14: Sandwich | C14: =IF(OR($B14="Unknown",$B14="Error",$B14=""),IFERROR(VLOOKUP($H14, '02_UnitPriceRef'!$F$3:$G$10,2,FALSE),"N/A"),$B14) -> Sandwich | D14: Sandwich | E14: 2 | F14: =IF(OR($E14="ERROR",$E14="UNKNOWN",$E14=""),IFERROR(I14/H14,0),E14) -> 2 | G14: 4 | H14: =IF(OR($G14="ERROR",$G14="UNKNOWN",$G14=""),IFERROR(VLOOKUP($D14,'02_UnitPriceRef'!$E$3:$F$10,2,0),IF(OR($E14="Error",$E14="UNKNOWN",$E14=""),0,I14/E14)),$G14) -> 4 | I14: 8 | J14: =F14*H14 -> 8 | K14: Cash | L14: In-store | M14: 45049 | N14: =IF(OR(M14="UNKNOWN",M14="ERROR",M14=""),DATE(1900,1,1),M14) -> 45049
A15: TXN_9437049 | B15: Cookie | C15: =IF(OR($B15="Unknown",$B15="Error",$B15=""),IFERROR(VLOOKUP($H15, '02_UnitPriceRef'!$F$3:$G$10,2,FALSE),"N/A"),$B15) -> Cookie | D15: Cookie | E15: 5 | F15: =IF(OR($E15="ERROR",$E15="UNKNOWN",$E15=""),IFERROR(I15/H15,0),E15) -> 5 | G15: 1 | H15: =IF(OR($G15="ERROR",$G15="UNKNOWN",$G15=""),IFERROR(VLOOKUP($D15,'02_UnitPriceRef'!$E$3:$F$10,2,0),IF(OR($E15="Error",$E15="UNKNOWN",$E15=""),0,I15/E15)),$G15) -> 1 | I15: 5 | J15: =F15*H15 -> 5 | K15: N/A | L15: Takeaway | M15: 45078 | N15: =IF(OR(M15="UNKNOWN",M15="ERROR",M15=""),DATE(1900,1,1),M15) -> 45078
A16: TXN_8915701 | B16: ERROR | C16: =IF(OR($B16="Unknown",$B16="Error",$B16=""),IFERROR(VLOOKUP($H16, '02_UnitPriceRef'!$F$3:$G$10,2,FALSE),"N/A"),$B16) -> Tea | D16: Tea | E16: 2 | F16: =IF(OR($E16="ERROR",$E16="UNKNOWN",$E16=""),IFERROR(I16/H16,0),E16) -> 2 | G16: 1.5 | H16: =IF(OR($G16="ERROR",$G16="UNKNOWN",$G16=""),IFERROR(VLOOKUP($D16,'02_UnitPriceRef'!$E$3:$F$10,2,0),IF(OR($E16="Error",$E16="UNKNOWN",$E16=""),0,I16/E16)),$G16) -> 1.5 | I16: 3 | J16: =F16*H16 -> 3 | K16: N/A | L16: In-store | M16: 45006 | N16: =IF(OR(M16="UNKNOWN",M16="ERROR",M16=""),DATE(1900,1,1),M16) -> 45006
A17: TXN_2847255 | B17: Salad | C17: =IF(OR($B17="Unknown",$B17="Error",$B17=""),IFERROR(VLOOKUP($H17, '02_UnitPriceRef'!$F$3:$G$10,2,FALSE),"N/A"),$B17) -> Salad | D17: Salad | E17: 3 | F17: =IF(OR($E17="ERROR",$E17="UNKNOWN",$E17=""),IFERROR(I17/H17,0),E17) -> 3 | G17: 5 | H17: =IF(OR($G17="ERROR",$G17="UNKNOWN",$G17=""),IFERROR(VLOOKUP($D17,'02_UnitPriceRef'!$E$3:$F$10,2,0),IF(OR($E17="Error",$E17="UNKNOWN",$E17=""),0,I17/E17)),$G17) -> 5 | I17: 15 | J17: =F17*H17 -> 15 | K17: Credit Card | L17: In-store | M17: 45245 | N17: =IF(OR(M17="UNKNOWN",M17="ERROR",M17=""),DATE(1900,1,1),M17) -> 45245
A18: TXN_3765707 | B18: Sandwich | C18: =IF(OR($B18="Unknown",$B18="Error",$B18=""),IFERROR(VLOOKUP($H18, '02_UnitPriceRef'!$F$3:$G$10,2,FALSE),"N/A"),$B18) -> Sandwich | D18: Sandwich | E18: 1 | F18: =IF(OR($E18="ERROR",$E18="UNKNOWN",$E18=""),IFERROR(I18/H18,0),E18) -> 1 | G18: 4 | H18: =IF(OR($G18="ERROR",$G18="UNKNOWN",$G18=""),IFERROR(VLOOKUP($D18,'02_UnitPriceRef'!$E$3:$F$10,2,0),IF(OR($E18="Error",$E18="UNKNOWN",$E18=""),0,I18/E18)),$G18) -> 4 | I18: 4 | J18: =F18*H18 -> 4 | K18: N/A | L18: N/A | M18: 45087 | N18: =IF(OR(M18="UNKNOWN",M18="ERROR",M18=""),DATE(1900,1,1),M18) -> 45087
A19: TXN_6769710 | B19: Juice | C19: =IF(OR($B19="Unknown",$B19="Error",$B19=""),IFERROR(VLOOKUP($H19, '02_UnitPriceRef'!$F$3:$G$10,2,FALSE),"N/A"),$B19) -> Juice | D19: Juice | E19: 2 | F19: =IF(OR($E19="ERROR",$E19="UNKNOWN",$E19=""),IFERROR(I19/H19,0),E19) -> 2 | G19: 3 | H19: =IF(OR($G19="ERROR",$G19="UNKNOWN",$G19=""),IFERROR(VLOOKUP($D19,'02_UnitPriceRef'!$E$3:$F$10,2,0),IF(OR($E19="Error",$E19="UNKNOWN",$E19=""),0,I19/E19)),$G19) -> 3 | I19: 6 | J19: =F19*H19 -> 6 | K19: Cash | L19: In-store | M19: 44981 | N19: =IF(OR(M19="UNKNOWN",M19="ERROR",M19=""),DATE(1900,1,1),M19) -> 44981
A20: TXN_8876618 | B20: Cake | C20: =IF(OR($B20="Unknown",$B20="Error",$B20=""),IFERROR(VLOOKUP($H20, '02_UnitPriceRef'!$F$3:$G$10,2,FALSE),"N/A"),$B20) -> Cake | D20: Cake | E20: 5 | F20: =IF(OR($E20="ERROR",$E20="UNKNOWN",$E20=""),IFERROR(I20/H20,0),E20) -> 5 | G20: 3 | H20: =IF(OR($G20="ERROR",$G20="UNKNOWN",$G20=""),IFERROR(VLOOKUP($D20,'02_UnitPriceRef'!$E$3:$F$10,2,0),IF(OR($E20="Error",$E20="UNKNOWN",$E20=""),0,I20/E20)),$G20) -> 3 | I20: 15 | J20: =F20*H20 -> 15 | K20: Cash | L20: N/A | M20: 45010 | N20: =IF(OR(M20="UNKNOWN",M20="ERROR",M20=""),DATE(1900,1,1),M20) -> 45010
A21: TXN_3709394 | B21: Juice | C21: =IF(OR($B21="Unknown",$B21="Error",$B21=""),IFERROR(VLOOKUP($H21, '02_UnitPriceRef'!$F$3:$G$10,2,FALSE),"N/A"),$B21) -> Juice | D21: Juice | E21: 4 | F21: =IF(OR($E21="ERROR",$E21="UNKNOWN",$E21=""),IFERROR(I21/H21,0),E21) -> 4 | G21: 3 | H21: =IF(OR($G21="ERROR",$G21="UNKNOWN",$G21=""),IFERROR(VLOOKUP($D21,'02_UnitPriceRef'!$E$3:$F$10,2,0),IF(OR($E21="Error",$E21="UNKNOWN",$E21=""),0,I21/E21)),$G21) -> 3 | I21: 12 | J21: =F21*H21 -> 12 | K21: Cash | L21: Takeaway | M21: 44941 | N21: =IF(OR(M21="UNKNOWN",M21="ERROR",M21=""),DATE(1900,1,1),M21) -> 44941
A22: TXN_3522028 | B22: Smoothie | C22: =IF(OR($B22="Unknown",$B22="Error",$B22=""),IFERROR(VLOOKUP($H22, '02_UnitPriceRef'!$F$3:$G$10,2,FALSE),"N/A"),$B22) -> Smoothie | D22: Smoothie | E22: ERROR | F22: =IF(OR($E22="ERROR",$E22="UNKNOWN",$E22=""),IFERROR(I22/H22,0),E22) -> 5 | G22: 4 | H22: =IF(OR($G22="ERROR",$G22="UNKNOWN",$G22=""),IFERROR(VLOOKUP($D22,'02_UnitPriceRef'!$E$3:$F$10,2,0),IF(OR($E22="Error",$E22="UNKNOWN",$E22=""),0,I22/E22)),$G22) -> 4 | I22: 20 | J22: =F22*H22 -> 20 | K22: Cash | L22: In-store | M22: 45020 | N22: =IF(OR(M22="UNKNOWN",M22="ERROR",M22=""),DATE(1900,1,1),M22) -> 45020
A23: TXN_3567645 | B23: Smoothie | C23: =IF(OR($B23="Unknown",$B23="Error",$B23=""),IFERROR(VLOOKUP($H23, '02_UnitPriceRef'!$F$3:$G$10,2,FALSE),"N/A"),$B23) -> Smoothie | D23: Smoothie | E23: 4 | F23: =IF(OR($E23="ERROR",$E23="UNKNOWN",$E23=""),IFERROR(I23/H23,0),E23) -> 4 | G23: 4 | H23: =IF(OR($G23="ERROR",$G23="UNKNOWN",$G23=""),IFERROR(VLOOKUP($D23,'02_UnitPriceRef'!$E$3:$F$10,2,0),IF(OR($E23="Error",$E23="UNKNOWN",$E23=""),0,I23/E23)),$G23) -> 4 | I23: 16 | J23: =F23*H23 -> 16 | K23: Credit Card | L23: Takeaway | M23: 45015 | N23: =IF(OR(M23="UNKNOWN",M23="ERROR",M23=""),DATE(1900,1,1),M23) -> 45015
A24: TXN_5132361 | B24: Sandwich | C24: =IF(OR($B24="Unknown",$B24="Error",$B24=""),IFERROR(VLOOKUP($H24, '02_UnitPriceRef'!$F$3:$G$10,2,FALSE),"N/A"),$B24) -> Sandwich | D24: Sandwich | E24: 3 | F24: =IF(OR($E24="ERROR",$E24="UNKNOWN",$E24=""),IFERROR(I24/H24,0),E24) -> 3 | G24: 4 | H24: =IF(OR($G24="ERROR",$G24="UNKNOWN",$G24=""),IFERROR(VLOOKUP($D24,'02_UnitPriceRef'!$E$3:$F$10,2,0),IF(OR($E24="Error",$E24="UNKNOWN",$E24=""),0,I24/E24)),$G24) -> 4 | I24: 12 | J24: =F24*H24 -> 12 | K24: Digital Wallet | L24: Takeaway | M24: 45261 | N24: =IF(OR(M24="UNKNOWN",M24="ERROR",M24=""),DATE(1900,1,1),M24) -> 45261
A25: TXN_2616390 | B25: Sandwich | C25: =IF(OR($B25="Unknown",$B25="Error",$B25=""),IFERROR(VLOOKUP($H25, '02_UnitPriceRef'!$F$3:$G$10,2,FALSE),"N/A"),$B25) -> Sandwich | D25: Sandwich | E25: 2 | F25: =IF(OR($E25="ERROR",$E25="UNKNOWN",$E25=""),IFERROR(I25/H25,0),E25) -> 2 | G25: 4 | H25: =IF(OR($G25="ERROR",$G25="UNKNOWN",$G25=""),IFERROR(VLOOKUP($D25,'02_UnitPriceRef'!$E$3:$F$10,2,0),IF(OR($E25="Error",$E25="UNKNOWN",$E25=""),0,I25/E25)),$G25) -> 4 | I25: 8 | J25: =F25*H25 -> 8 | K25: N/A | L25: N/A | M25: 45187 | N25: =IF(OR(M25="UNKNOWN",M25="ERROR",M25=""),DATE(1900,1,1),M25) -> 45187
A26: TXN_9400181 | B26: Sandwich | C26: =IF(OR($B26="Unknown",$B26="Error",$B26=""),IFERROR(VLOOKUP($H26, '02_UnitPriceRef'!$F$3:$G$10,2,FALSE),"N/A"),$B26) -> Sandwich | D26: Sandwich | E26: 5 | F26: =IF(OR($E26="ERROR",$E26="UNKNOWN",$E26=""),IFERROR(I26/H26,0),E26) -> 5 | G26: 4 | H26: =IF(OR($G26="ERROR",$G26="UNKNOWN",$G26=""),IFERROR(VLOOKUP($D26,'02_UnitPriceRef'!$E$3:$F$10,2,0),IF(OR($E26="Error",$E26="UNKNOWN",$E26=""),0,I26/E26)),$G26) -> 4 | I26: 20 | J26: =F26*H26 -> 20 | K26: Cash | L26: In-store | M26: 45080 | N26: =IF(OR(M26="UNKNOWN",M26="ERROR",M26=""),DATE(1900,1,1),M26) -> 45080
A27: TXN_7958992 | B27: Smoothie | C27: =IF(OR($B27="Unknown",$B27="Error",$B27=""),IFERROR(VLOOKUP($H27, '02_UnitPriceRef'!$F$3:$G$10,2,FALSE),"N/A"),$B27) -> Smoothie | D27: Smoothie | E27: 3 | F27: =IF(OR($E27="ERROR",$E27="UNKNOWN",$E27=""),IFERROR(I27/H27,0),E27) -> 3 | G27: 4 | H27: =IF(OR($G27="ERROR",$G27="UNKNOWN",$G27=""),IFERROR(VLOOKUP($D27,'02_UnitPriceRef'!$E$3:$F$10,2,0),IF(OR($E27="Error",$E27="UNKNOWN",$E27=""),0,I27/E27)),$G27) -> 4 | J27: =F27*H27 -> 12 | K27: N/A | L27: N/A | M27: 45273 | N27: =IF(OR(M27="UNKNOWN",M27="ERROR",M27=""),DATE(1900,1,1),M27) -> 45273
A28: TXN_5183041 | B28: Cookie | C28: =IF(OR($B28="Unknown",$B28="Error",$B28=""),IFERROR(VLOOKUP($H28, '02_UnitPriceRef'!$F$3:$G$10,2,FALSE),"N/A"),$B28) -> Cookie | D28: Cookie | E28: 5 | F28: =IF(OR($E28="ERROR",$E28="UNKNOWN",$E28=""),IFERROR(I28/H28,0),E28) -> 5 | G28: 1 | H28: =IF(OR($G28="ERROR",$G28="UNKNOWN",$G28=""),IFERROR(VLOOKUP($D28,'02_UnitPriceRef'!$E$3:$F$10,2,0),IF(OR($E28="Error",$E28="UNKNOWN",$E28=""),0,I28/E28)),$G28) -> 1 | I28: 5 | J28: =F28*H28 -> 5 | K28: Credit Card | L28: In-store | M28: 45036 | N28: =IF(OR(M28="UNKNOWN",M28="ERROR",M28=""),DATE(1900,1,1),M28) -> 45036
A29: TXN_5695074 | B29: Juice | C29: =IF(OR($B29="Unknown",$B29="Error",$B29=""),IFERROR(VLOOKUP($H29, '02_UnitPriceRef'!$F$3:$G$10,2,FALSE),"N/A"),$B29) -> Juice | D29: Juice | E29: 4 | F29: =IF(OR($E29="ERROR",$E29="UNKNOWN",$E29=""),IFERROR(I29/H29,0),E29) -> 4 | G29: 3 | H29: =IF(OR($G29="ERROR",$G29="UNKNOWN",$G29=""),IFERROR(VLOOKUP($D29,'02_UnitPriceRef'!$E$3:$F$10,2,0),IF(OR($E29="Error",$E29="UNKNOWN",$E29=""),0,I29/E29)),$G29) -> 3 | I29: 12 | J29: =F29*H29 -> 12 | K29: Credit Card | L29: Takeaway | M29: 45026 | N29: =IF(OR(M29="UNKNOWN",M29="ERROR",M29=""),DATE(1900,1,1),M29) -> 45026
A30: TXN_8467949 | B30: Smoothie | C30: =IF(OR($B30="Unknown",$B30="Error",$B30=""),IFERROR(VLOOKUP($H30, '02_UnitPriceRef'!$F$3:$G$10,2,FALSE),"N/A"),$B30) -> Smoothie | D30: Smoothie | E30: 5 | F30: =IF(OR($E30="ERROR",$E30="UNKNOWN",$E30=""),IFERROR(I30/H30,0),E30) -> 5 | G30: 4 | H30: =IF(OR($G30="ERROR",$G30="UNKNOWN",$G30=""),IFERROR(VLOOKUP($D30,'02_UnitPriceRef'!$E$3:$F$10,2,0),IF(OR($E30="Error",$E30="UNKNOWN",$E30=""),0,I30/E30)),$G30) -> 4 | I30: 20 | J30: =F30*H30 -> 20 | K30: Credit Card | L30: N/A | M30: 44996 | N30: =IF(OR(M30="UNKNOWN",M30="ERROR",M30=""),DATE(1900,1,1),M30) -> 44996
A31: TXN_7640952 | B31: Cake | C31: =IF(OR($B31="Unknown",$B31="Error",$B31=""),IFERROR(VLOOKUP($H31, '02_UnitPriceRef'!$F$3:$G$10,2,FALSE),"N/A"),$B31) -> Cake | D31: Cake | E31: 4 | F31: =IF(OR($E31="ERROR",$E31="UNKNOWN",$E31=""),IFERROR(I31/H31,0),E31) -> 4 | G31: 3 | H31: =IF(OR($G31="ERROR",$G31="UNKNOWN",$G31=""),IFERROR(VLOOKUP($D31,'02_UnitPriceRef'!$E$3:$F$10,2,0),IF(OR($E31="Error",$E31="UNKNOWN",$E31=""),0,I31/E31)),$G31) -> 3 | I31: 12 | J31: =F31*H31 -> 12 | K31: Digital Wallet | L31: Takeaway | M31: ERROR | N31: =IF(OR(M31="UNKNOWN",M31="ERROR",M31=""),DATE(1900,1,1),M31) -> 1
A32: TXN_1736287 | C32: =IF(OR($B32="Unknown",$B32="Error",$B32=""),IFERROR(VLOOKUP($H32, '02_UnitPriceRef'!$F$3:$G$10,2,FALSE),"N/A"),$B32) -> Coffee | D32: Coffee | E32: 5 | F32: =IF(OR($E32="ERROR",$E32="UNKNOWN",$E32=""),IFERROR(I32/H32,0),E32) -> 5 | G32: 2 | H32: =IF(OR($G32="ERROR",$G32="UNKNOWN",$G32=""),IFERROR(VLOOKUP($D32,'02_UnitPriceRef'!$E$3:$F$10,2,0),IF(OR($E32="Error",$E32="UNKNOWN",$E32=""),0,I32/E32)),$G32) -> 2 | I32: 10 | J32: =F32*H32 -> 10 | K32: Digital Wallet | L32: N/A | M32: 45079 | N32: =IF(OR(M32="UNKNOWN",M32="ERROR",M32=""),DATE(1900,1,1),M32) -> 45079
A33: TXN_8927252 | B33: UNKNOWN | C33: =IF(OR($B33="Unknown",$B33="Error",$B33=""),IFERROR(VLOOKUP($H33, '02_UnitPriceRef'!$F$3:$G$10,2,FALSE),"N/A"),$B33) -> Cookie | D33: Cookie | E33: 2 | F33: =IF(OR($E33="ERROR",$E33="UNKNOWN",$E33=""),IFERROR(I33/H33,0),E33) -> 2 | G33: 1 | H33: =IF(OR($G33="ERROR",$G33="UNKNOWN",$G33=""),IFERROR(VLOOKUP($D33,'02_UnitPriceRef'!$E$3:$F$10,2,0),IF(OR($E33="Error",$E33="UNKNOWN",$E33=""),0,I33/E33)),$G33) -> 1 | I33: ERROR | J33: =F33*H33 -> 2 | K33: Credit Card | L33: N/A | M33: 45236 | N33: =IF(OR(M33="UNKNOWN",M33="ERROR",M33=""),DATE(1900,1,1),M33) -> 45236
A34: TXN_9677376 | B34: Smoothie | C34: =IF(OR($B34="Unknown",$B34="Error",$B34=""),IFERROR(VLOOKUP($H34, '02_UnitPriceRef'!$F$3:$G$10,2,FALSE),"N/A"),$B34) -> Smoothie | D34: Smoothie | E34: 4 | F34: =IF(OR($E34="ERROR",$E34="UNKNOWN",$E34=""),IFERROR(I34/H34,0),E34) -> 4 | G34: 4 | H34: =IF(OR($G34="ERROR",$G34="UNKNOWN",$G34=""),IFERROR(VLOOKUP($D34,'02_UnitPriceRef'!$E$3:$F$10,2,0),IF(OR($E34="Error",$E34="UNKNOWN",$E34=""),0,I34/E34)),$G34) -> 4 | I34: 16 | J34: =F34*H34 -> 16 | K34: N/A | L34: In-store | M34: 45153 | N34: =IF(OR(M34="UNKNOWN",M34="ERROR",M34=""),DATE(1900,1,1),M34) -> 45153
A35: TXN_7710508 | B35: UNKNOWN | C35: =IF(OR($B35="Unknown",$B35="Error",$B35=""),IFERROR(VLOOKUP($H35, '02_UnitPriceRef'!$F$3:$G$10,2,FALSE),"N/A"),$B35) -> Cookie | D35: Cookie | E35: 5 | F35: =IF(OR($E35="ERROR",$E35="UNKNOWN",$E35=""),IFERROR(I35/H35,0),E35) -> 5 | G35: 1 | H35: =IF(OR($G35="ERROR",$G35="UNKNOWN",$G35=""),IFERROR(VLOOKUP($D35,'02_UnitPriceRef'!$E$3:$F$10,2,0),IF(OR($E35="Error",$E35="UNKNOWN",$E35=""),0,I35/E35)),$G35) -> 1 | I35: 5 | J35: =F35*H35 -> 5 | K35: Cash | L35: N/A | M35: ERROR | N35: =IF(OR(M35="UNKNOWN",M35="ERROR",M35=""),DATE(1900,1,1),M35) -> 1
A36: TXN_8853997 | B36: Smoothie | C36: =IF(OR($B36="Unknown",$B36="Error",$B36=""),IFERROR(VLOOKUP($H36, '02_UnitPriceRef'!$F$3:$G$10,2,FALSE),"N/A"),$B36) -> Smoothie | D36: Smoothie | E36: 2 | F36: =IF(OR($E36="ERROR",$E36="UNKNOWN",$E36=""),IFERROR(I36/H36,0),E36) -> 2 | G36: 4 | H36: =IF(OR($G36="ERROR",$G36="UNKNOWN",$G36=""),IFERROR(VLOOKUP($D36,'02_UnitPriceRef'!$E$3:$F$10,2,0),IF(OR($E36="Error",$E36="UNKNOWN",$E36=""),0,I36/E36)),$G36) -> 4 | I36: 8 | J36: =F36*H36 -> 8 | K36: Digital Wallet | L36: Takeaway | M36: 45208 | N36: =IF(OR(M36="UNKNOWN",M36="ERROR",M36=""),DATE(1900,1,1),M36) -> 45208
A37: TXN_9130559 | B37: Sandwich | C37: =IF(OR($B37="Unknown",$B37="Error",$B37=""),IFERROR(VLOOKUP($H37, '02_UnitPriceRef'!$F$3:$G$10,2,FALSE),"N/A"),$B37) -> Sandwich | D37: Sandwich | E37: 1 | F37: =IF(OR($E37="ERROR",$E37="UNKNOWN",$E37=""),IFERROR(I37/H37,0),E37) -> 1 | G37: 4 | H37: =IF(OR($G37="ERROR",$G37="UNKNOWN",$G37=""),IFERROR(VLOOKUP($D37,'02_UnitPriceRef'!$E$3:$F$10,2,0),IF(OR($E37="Error",$E37="UNKNOWN",$E37=""),0,I37/E37)),$G37) -> 4 | I37: 4 | J37: =F37*H37 -> 4 | K37: Credit Card | L37: N/A | M37: 45074 | N37: =IF(OR(M37="UNKNOWN",M37="ERROR",M37=""),DATE(1900,1,1),M37) -> 45074
A38: TXN_6855453 | B38: UNKNOWN | C38: =IF(OR($B38="Unknown",$B38="Error",$B38=""),IFERROR(VLOOKUP($H38, '02_UnitPriceRef'!$F$3:$G$10,2,FALSE),"N/A"),$B38) -> Cake/Juice | D38: Cake/Juice | E38: 4 | F38: =IF(OR($E38="ERROR",$E38="UNKNOWN",$E38=""),IFERROR(I38/H38,0),E38) -> 4 | G38: 3 | H38: =IF(OR($G38="ERROR",$G38="UNKNOWN",$G38=""),IFERROR(VLOOKUP($D38,'02_UnitPriceRef'!$E$3:$F$10,2,0),IF(OR($E38="Error",$E38="UNKNOWN",$E38=""),0,I38/E38)),$G38) -> 3 | I38: 12 | J38: =F38*H38 -> 12 | K38: N/A | L38: In-store | M38: 45124 | N38: =IF(OR(M38="UNKNOWN",M38="ERROR",M38=""),DATE(1900,1,1),M38) -> 45124
A39: TXN_1080432 | B39: Salad | C39: =IF(OR($B39="Unknown",$B39="Error",$B39=""),IFERROR(VLOOKUP($H39, '02_UnitPriceRef'!$F$3:$G$10,2,FALSE),"N/A"),$B39) -> Salad | D39: Salad | E39: 2 | F39: =IF(OR($E39="ERROR",$E39="UNKNOWN",$E39=""),IFERROR(I39/H39,0),E39) -> 2 | G39: 5 | H39: =IF(OR($G39="ERROR",$G39="UNKNOWN",$G39=""),IFERROR(VLOOKUP($D39,'02_UnitPriceRef'!$E$3:$F$10,2,0),IF(OR($E39="Error",$E39="UNKNOWN",$E39=""),0,I39/E39)),$G39) -> 5 | I39: 10 | J39: =F39*H39 -> 10 | K39: Credit Card | L39: In-store | M39: 45045 | N39: =IF(OR(M39="UNKNOWN",M39="ERROR",M39=""),DATE(1900,1,1),M39) -> 45045
A40: TXN_2655815 | B40: Smoothie | C40: =IF(OR($B40="Unknown",$B40="Error",$B40=""),IFERROR(VLOOKUP($H40, '02_UnitPriceRef'!$F$3:$G$10,2,FALSE),"N/A"),$B40) -> Smoothie | D40: Smoothie | E40: 4 | F40: =IF(OR($E40="ERROR",$E40="UNKNOWN",$E40=""),IFERROR(I40/H40,0),E40) -> 4 | G40: 4 | H40: =IF(OR($G40="ERROR",$G40="UNKNOWN",$G40=""),IFERROR(VLOOKUP($D40,'02_UnitPriceRef'!$E$3:$F$10,2,0),IF(OR($E40="Error",$E40="UNKNOWN",$E40=""),0,I40/E40)),$G40) -> 4 | I40: 16 | J40: =F40*H40 -> 16 | K40: N/A | L40: Takeaway | M40: 45085 | N40: =IF(OR(M40="UNKNOWN",M40="ERROR",M40=""),DATE(1900,1,1),M40) -> 45085
...

Sheet 02_UnitPriceRef
A1: Cleaned_Item | B1: Price Per Unit
A2: Cake | B2: 3 | E2: Unique_Item | F2: Price Per Unit
B3: (blank) | E3: Cake | F3: 3 | G3: Cake/Juice
A4: Cake Total | E4: Coffee | F4: 2 | G4: Coffee
A5: Coffee | B5: 2 | E5: Cookie | F5: 1 | G5: Cookie
B6: (blank) | E6: Juice | F6: 3 | G6: Juice/Juice
A7: Coffee Total | E7: Salad | F7: 5 | G7: Salad
A8: Cookie | B8: 1 | E8: Sandwich | F8: 4 | G8: Sandwich/Smoothie
B9: (blank) | E9: Smoothie | F9: 4 | G9: Sandwich/Smoothie
A10: Cookie Total | E10: Tea | F10: 1.5 | G10: Tea
A11: Juice | B11: 3
B12: (blank)
A13: Juice Total
A14: N/A | B14: (blank)
A15: N/A Total
A16: Salad | B16: 5
B17: (blank)
A18: Salad Total
A19: Sandwich | B19: 4
B20: (blank)
A21: Sandwich Total
A22: Sandwich/Smoothie | B22: 4
A23: Sandwich/Smoothie Total
A24: Smoothie | B24: 4
B25: (blank)
A26: Smoothie Total
A27: Tea | B27: 1.5
B28: (blank)
A29: Tea Total

Sheet 01_Raw_Data
A1: Transaction ID | B1: Item | C1: Quantity | D1: Price Per Unit | E1: Total Spent | F1: Payment Method | G1: Location | H1: Transaction Date
A2: TXN_1961373 | B2: Coffee | C2: 2 | D2: 2 | E2: 4 | F2: Credit Card | G2: Takeaway | H2: 45177
A3: TXN_4977031 | B3: Cake | C3: 4 | D3: 3 | E3: 12 | F3: Cash | G3: In-store | H3: 45062
A4: TXN_4271903 | B4: Cookie | C4: 4 | D4: 1 | E4: ERROR | F4: Credit Card | G4: In-store | H4: 45126
A5: TXN_7034554 | B5: Salad | C5: 2 | D5: 5 | E5: 10 | F5: UNKNOWN | G5: UNKNOWN | H5: 45043
A6: TXN_3160411 | B6: Coffee | C6: 2 | D6: 2 | E6: 4 | F6: Digital Wallet | G6: In-store | H6: 45088
A7: TXN_2602893 | B7: Smoothie | C7: 5 | D7: 4 | E7: 20 | F7: Credit Card | H7: 45016
A8: TXN_4433211 | B8: UNKNOWN | C8: 3 | D8: 3 | E8: 9 | F8: ERROR | G8: Takeaway | H8: 45205
A9: TXN_6699534 | B9: Sandwich | C9: 4 | D9: 4 | E9: 16 | F9: Cash | G9: UNKNOWN | H9: 45227
A10: TXN_4717867 | C10: 5 | D10: 3 | E10: 15 | G10: Takeaway | H10: 45135
A11: TXN_2064365 | B11: Sandwich | C11: 5 | D11: 4 | E11: 20 | G11: In-store | H11: 45291
A12: TXN_2548360 | B12: Salad | C12: 5 | D12: 5 | E12: 25 | F12: Cash | G12: Takeaway | H12: 45237
A13: TXN_3051279 | B13: Sandwich | C13: 2 | D13: 4 | E13: 8 | F13: Credit Card | G13: Takeaway | H13: ERROR
A14: TXN_7619095 | B14: Sandwich | C14: 2 | D14: 4 | E14: 8 | F14: Cash | G14: In-store | H14: 45049
A15: TXN_9437049 | B15: Cookie | C15: 5 | D15: 1 | E15: 5 | G15: Takeaway | H15: 45078
A16: TXN_8915701 | B16: ERROR | C16: 2 | D16: 1.5 | E16: 3 | G16: In-store | H16: 45006
A17: TXN_2847255 | B17: Salad | C17: 3 | D17: 5 | E17: 15 | F17: Credit Card | G17: In-store | H17: 45245
A18: TXN_3765707 | B18: Sandwich | C18: 1 | D18: 4 | E18: 4 | H18: 45087
A19: TXN_6769710 | B19: Juice | C19: 2 | D19: 3 | E19: 6 | F19: Cash | G19: In-store | H19: 44981
A20: TXN_8876618 | B20: Cake | C20: 5 | D20: 3 | E20: 15 | F20: Cash | G20: ERROR | H20: 45010
A21: TXN_3709394 | B21: Juice | C21: 4 | D21: 3 | E21: 12 | F21: Cash | G21: Takeaway | H21: 44941
A22: TXN_3522028 | B22: Smoothie | C22: ERROR | D22: 4 | E22: 20 | F22: Cash | G22: In-store | H22: 45020
A23: TXN_3567645 | B23: Smoothie | C23: 4 | D23: 4 | E23: 16 | F23: Credit Card | G23: Takeaway | H23: 45015
A24: TXN_5132361 | B24: Sandwich | C24: 3 | D24: 4 | E24: 12 | F24: Digital Wallet | G24: Takeaway | H24: 45261
A25: TXN_2616390 | B25: Sandwich | C25: 2 | D25: 4 | E25: 8 | H25: 45187
A26: TXN_9400181 | B26: Sandwich | C26: 5 | D26: 4 | E26: 20 | F26: Cash | G26: In-store | H26: 45080
A27: TXN_7958992 | B27: Smoothie | C27: 3 | D27: 4 | F27: UNKNOWN | G27: UNKNOWN | H27: 45273
A28: TXN_5183041 | B28: Cookie | C28: 5 | D28: 1 | E28: 5 | F28: Credit Card | G28: In-store | H28: 45036
A29: TXN_5695074 | B29: Juice | C29: 4 | D29: 3 | E29: 12 | F29: Credit Card | G29: Takeaway | H29: 45026
A30: TXN_8467949 | B30: Smoothie | C30: 5 | D30: 4 | E30: 20 | F30: Credit Card | H30: 44996
A31: TXN_7640952 | B31: Cake | C31: 4 | D31: 3 | E31: 12 | F31: Digital Wallet | G31: Takeaway | H31: ERROR
A32: TXN_1736287 | C32: 5 | D32: 2 | E32: 10 | F32: Digital Wallet | H32: 45079
A33: TXN_8927252 | B33: UNKNOWN | C33: 2 | D33: 1 | E33: ERROR | F33: Credit Card | G33: ERROR | H33: 45236
A34: TXN_9677376 | B34: Smoothie | C34: 4 | D34: 4 | E34: 16 | G34: In-store | H34: 45153
A35: TXN_7710508 | B35: UNKNOWN | C35: 5 | D35: 1 | E35: 5 | F35: Cash | H35: ERROR
A36: TXN_8853997 | B36: Smoothie | C36: 2 | D36: 4 | E36: 8 | F36: Digital Wallet | G36: Takeaway | H36: 45208
A37: TXN_9130559 | B37: Sandwich | C37: 1 | D37: 4 | E37: 4 | F37: Credit Card | G37: UNKNOWN | H37: 45074
A38: TXN_6855453 | B38: UNKNOWN | C38: 4 | D38: 3 | E38: 12 | G38: In-store | H38: 45124
A39: TXN_1080432 | B39: Salad | C39: 2 | D39: 5 | E39: 10 | F39: Credit Card | G39: In-store | H39: 45045
A40: TXN_2655815 | B40: Smoothie | C40: 4 | D40: 4 | E40: 16 | G40: Takeaway | H40: 45085
...
